Workbook

Sheet Sheet5
A3: Row Labels | B3: Count of Weekly_Entertainment_Hours
A4: 17 | B4: 51
A5: 9 | B5: 46
A6: 22 | B6: 46
A7: 8 | B7: 46
A8: 23 | B8: 44
A9: 18 | B9: 44
A10: 21 | B10: 43
A11: 26 | B11: 42
A12: 6 | B12: 42
A13: 11 | B13: 40
A14: 12 | B14: 38
A15: 20 | B15: 38
... A29: 30 | B29: 29
A30: Grand Total | B30: 1000

Sheet Sheet7
A1: City_Type | B1: (All)
A3: Sum of Monthly_Spending_INR | B3: Column Labels
A4: Row Labels | B4: Action | C4: Comedy | D4: Drama | E4: Horror | F4: Pop | G4: Romance | H4: Sports | I4: Thriller | J4: Grand Total
A5: Female | B5: 65378 | C5: 66179 | D5: 87860 | E5: 82041 | F5: 48552 | G5: 58173 | H5: 70019 | I5: 57595 | J5: 535797
A6: Male | B6: 55789 | C6: 70833 | D6: 53570 | E6: 56512 | F6: 53082 | G6: 68590 | H6: 77491 | I6: 68777 | J6: 504644
A7: Other | B7: 54873 | C7: 65883 | D7: 74686 | E7: 50616 | F7: 50007 | G7: 67092 | H7: 68871 | I7: 65916 | J7: 497944
A8: Grand Total | B8: 176040 | C8: 202895 | D8: 216116 | E8: 189169 | F8: 151641 | G8: 193855 | H8: 216381 | I8: 192288 | J8: 1538385

Sheet Entertainment_Preferences
A1: Respondent_ID | B1: Age | C1: Gender | D1: City_Type | E1: Education_Level | F1: Preferred_Entertainment_Type | G1: Weekly_Entertainment_Hours | H1: Primary_Platform | I1: Monthly_Spending_INR | J1: Preferred_Genre | K1: Device_Used | L1: Subscription_Status | M1: Social_Influence | N1: Satisfaction_Level_1_to_5
A2: 1 | B2: 38 | C2: Male | D2: Metro | E2: School | F2: Live Events | G2: 8 | H2: Amazon Prime | I2: 102 | J2: Drama | K2: Tablet | L2: Paid | M2: Yes | N2: 3
A3: 2 | B3: 20 | C3: Other | D3: Metro | E3: PG | F3: Music | G3: 11 | H3: Theatre | I3: 952 | J3: Horror | K3: Tablet | L3: Free | M3: Yes | N3: 5
A4: 3 | B4: 23 | C4: Female | D4: Metro | E4: School | F4: Gaming | G4: 27 | H4: Amazon Prime | I4: 1731 | J4: Drama | K4: Tablet | L4: Paid | M4: No | N4: 3
A5: 4 | B5: 29 | C5: Other | D5: Urban | E5: PG | F5: Movies | G5: 24 | H5: Theatre | I5: 1083 | J5: Drama | K5: TV | L5: Free | M5: Yes | N5: 1
A6: 5 | B6: 40 | C6: Female | D6: Metro | E6: School | F6: Movies | G6: 7 | H6: Theatre | I6: 187 | J6: Romance | K6: Tablet | L6: Free | M6: Yes | N6: 2
A7: 6 | B7: 29 | C7: Other | D7: Rural | E7: PG | F7: Movies | G7: 16 | H7: Hotstar | I7: 858 | J7: Horror | K7: Laptop | L7: Free | M7: No | N7: 3
A8: 7 | B8: 26 | C8: Male | D8: Rural | E8: UG | F8: Movies | G8: 25 | H8: YouTube | I8: 2818 | J8: Action | K8: TV | L8: Free | M8: No | N8: 5
A9: 8 | B9: 20 | C9: Male | D9: Rural | E9: UG | F9: OTT | G9: 11 | H9: PlayStation | I9: 2323 | J9: Comedy | K9: TV | L9: Paid | M9: Yes | N9: 3
A10: 9 | B10: 35 | C10: Female | D10: Rural | E10: UG | F10: Gaming | G10: 22 | H10: YouTube | I10: 1076 | J10: Comedy | K10: Tablet | L10: Paid | M10: Yes | N10: 5
A11: 10 | B11: 21 | C11: Other | D11: Urban | E11: PG | F11: Movies | G11: 9 | H11: Theatre | I11: 2570 | J11: Sports | K11: Tablet | L11: Free | M11: Yes | N11: 2
A12: 11 | B12: 39 | C12: Female | D12: Rural | E12: UG | F12: Movies | G12: 28 | H12: Spotify | I12: 469 | J12: Sports | K12: Laptop | L12: Free | M12: Yes | N12: 5
A13: 12 | B13: 26 | C13: Male | D13: Rural | E13: UG | F13: Live Events | G13: 21 | H13: YouTube | I13: 731 | J13: Comedy | K13: TV | L13: Paid | M13: Yes | N13: 5
... A1001: 1000 | B1001: 37 | C1001: Male | D1001: Rural | E1001: UG | F1001: OTT | G1001: 17 | H1001: Hotstar | I1001: 2584 | J1001: Romance | K1001: Laptop | L1001: Free | M1001: No | N1001: 5

Sheet Sheet1
A3: G+A3:B28Row Labels | B3: Sum of Monthly_Spending_INR
A4: 5 | B4: 45676
A5: 6 | B5: 67805
A6: 7 | B6: 49296
A7: 8 | B7: 60167
A8: 9 | B8: 72258
A9: 10 | B9: 52154
A10: 11 | B10: 58858
A11: 12 | B11: 60165
A12: 13 | B12: 44288
A13: 14 | B13: 46521
A14: 15 | B14: 67557
A15: 16 | B15: 41247
... A29: 30 | B29: 53106
A30: Grand Total | B30: 1538385

Sheet Sheet2
A3: 1. Which entertainment type is most preferred?
A4: preferred Entertainment Type | B4: Count of Preferred_Entertainment_Type
A5: Sports | B5: 181
A6: OTT | B6: 167
A7: Live Events | B7: 167
A8: Movies | B8: 165
A9: Gaming | B9: 162
A10: Music | B10: 158
A11: Grand Total | B11: 1000
A18: 2. How many hours do people spend weekly on entertainment? | D18: Weekly_Entertainment_Hours | E18: 8 | F18: 11 | G18: 27 | H18: 24 | I18: 7 | J18: 16 | K18: 25 | L18: 11 | M18: 22 | N18: 9 | O18: 28 | P18: 21 | Q18: 15 | R18: 29 | S18: 14 | T18: 22 | U18: 21 | V18: 8 | W18: 12 | X18: 30 | Y18: 11 | Z18: 11 | AA18: 21 | AB18: 24 | AC18: 17 | AD18: 16 | AE18: 8 | AF18: 6 | AG18: 5 | AH18: 16 | AI18: 30 | AJ18: 6 | AK18: 13 | AL18: 13 | AM18: 6 | AN18: 15 | AO18: 18 | AP18: 18 | AQ18: 21 | AR18: 12 | AS18: 25 | AT18: 30 | AU18: 29 | AV18: 15 | AW18: 15 | AX18: 14 | AY18: 5 | AZ18: 23 | BA18: 11 | BB18: 12 | BC18: 26 | BD18: 23 | BE18: 24 | BF18: 8 | BG18: 28 | BH18: 20 | BI18: 12 | BJ18: 12 | BK18: 19 | BL18: 28 | BM18: 10 | BN18: 5 | BO18: 17 | BP18: 22 | BQ18: 23 | BR18: 22 | BS18: 14 | BT18: 9 | BU18: 17 | BV18: 12 | BW18: 23 | BX18: 27 | BY18: 29 | BZ18: 19 | CA18: 10 | CB18: 27 | CC18: 24 | CD18: 19 | CE18: 17 | CF18: 21 | CG18: 20 | CH18: 6 | CI18: 10 | CJ18: 21 | CK18: 19 | CL18: 23 | CM18: 23 | CN18: 29 | CO18: 6 | CP18: 16 | CQ18: 29 | CR18: 28 | CS18: 12 | CT18: 20 | CU18: 8 | CV18: 8 | CW18: 26 | CX18: 15 | CY18: 16 | CZ18: 19 | DA18: 20 | DB18: 9 | DC18: 30 | DD18: 19 | DE18: 7 | DF18: 16 | DG18: 20 | DH18: 10 | DI18: 28 | DJ18: 9 | DK18: 11 | DL18: 6 | DM18: 10 | DN18: 19 | DO18: 10 | DP18: 14 | DQ18: 8 | DR18: 23 | DS18: 23 | DT18: 25 | DU18: 9 | DV18: 21 | DW18: 8 | DX18: 25 | DY18: 26 | DZ18: 9 | EA18: 10 | EB18: 12 | EC18: 11 | ED18: 13 | EE18: 21 | EF18: 6 | EG18: 9 | EH18: 25 | EI18: 24 | EJ18: 6 | EK18: 28 | EL18: 27 | EM18: 6 | EN18: 28 | EO18: 18 | EP18: 27 | EQ18: 26 | ER18: 7 | ES18: 23 | ET18: 21 | EU18: 9 | EV18: 27 | EW18: 22 | EX18: 18 | EY18: 25 | EZ18: 27 | FA18: 25 | FB18: 29 | FC18: 30 | FD18: 11 | FE18: 12 | FF18: 10 | FG18: 7 | FH18: 25 | FI18: 6 | FJ18: 26 | FK18: 6 | FL18: 17 | FM18: 26 | FN18: 20 | FO18: 19 | FP18: 15 | FQ18: 12 | FR18: 30 | FS18: 14 | FT18: 8 | FU18: 27 | FV18: 15 | FW18: 30 | FX18: 22 | FY18: 13 | FZ18: 17 | GA18: 29 | GB18: 8 | GC18: 9 | GD18: 19 | GE18: 26 | GF18: 6 | GG18: 18 | GH18: 28 | GI18: 22 | GJ18: 12 | GK18: 7 | GL18: 22 | GM18: 21 | GN18: 26 | GO18: 12 | GP18: 15 | GQ18: 11 | GR18: 12 | GS18: 13 | GT18: 6 | GU18: 17 | GV18: 28 | GW18: 18 | GX18: 20 | GY18: 8 | GZ18: 17 | HA18: 22 | HB18: 6 | HC18: 5 | HD18: 29 | HE18: 29 | HF18: 17 | HG18: 9 | HH18: 29 | HI18: 22 | HJ18: 21 | HK18: 13 | HL18: 14 | HM18: 24 | HN18: 13 | HO18: 27 | HP18: 7 | HQ18: 26 | HR18: 13 | HS18: 23 | HT18: 16 | HU18: 7 | HV18: 22 | HW18: 23 | HX18: 11 | HY18: 19 | HZ18: 8 | IA18: 25 | IB18: 5 | IC18: 10 | ID18: 28 | IE18: 8 | IF18: 30 | IG18: 16 | IH18: 6 | II18: 25 | IJ18: 15 | IK18: 20 | IL18: 25 | IM18: 13 | IN18: 25 | IO18: 15 | IP18: 16 | IQ18: 28 | IR18: 28 | IS18: 14 | IT18: 8 | IU18: 18 | IV18: 6 | IW18: 7 | IX18: 6 | IY18: 9 | IZ18: 29 | JA18: 20 | JB18: 6 | JC18: 13 | JD18: 19 | JE18: 12 | JF18: 22 | JG18: 6 | JH18: 9 | JI18: 30 | JJ18: 10 | JK18: 8 | JL18: 12 | JM18: 28 | JN18: 17 | JO18: 30 | JP18: 18 | JQ18: 18 | JR18: 30 | JS18: 24 | JT18: 12 | JU18: 15 | JV18: 20 | JW18: 15 | JX18: 26 | JY18: 27 | JZ18: 28 | KA18: 28 | KB18: 12 | KC18: 18 | KD18: 14 | KE18: 24 | KF18: 11 | KG18: 17 | KH18: 8 | KI18: 26 | KJ18: 13 | KK18: 18 | KL18: 17 | KM18: 30 | KN18: 7 | KO18: 9 | KP18: 25 | KQ18: 15 | KR18: 20 | KS18: 19 | KT18: 29 | KU18: 27 | KV18: 19 | KW18: 6 | KX18: 9 | KY18: 13 | KZ18: 26 | LA18: 21 | LB18: 17 | LC18: 26 | LD18: 12 | LE18: 23 | LF18: 9 | LG18: 10 | LH18: 18 | LI18: 29 | LJ18: 17 | LK18: 9 | LL18: 23 | LM18: 8 | LN18: 9 | LO18: 8 | LP18: 22 | LQ18: 7 | LR18: 8 | LS18: 26 | LT18: 17 | LU18: 8 | LV18: 20 | LW18: 26 | LX18: 20 | LY18: 12 | LZ18: 5 | MA18: 16 | MB18: 12 | MC18: 27 | MD18: 27 | ME18: 21 | MF18: 24 | MG18: 30 | MH18: 27 | MI18: 23 | MJ18: 6 | MK18: 6 | ML18: 17 | MM18: 22 | MN18: 6 | MO18: 9 | MP18: 12 | MQ18: 15 | MR18: 25 | MS18: 21 | MT18: 29 | MU18: 7 | MV18: 22 | MW18: 26 | MX18: 30 | MY18: 12 | MZ18: 5 | NA18: 21 | NB18: 22 | NC18: 25 | ND18: 23 | NE18: 28 | NF18: 20 | NG18: 5 | NH18: 17 | NI18: 26 | NJ18: 12 | NK18: 6 | NL18: 23 | NM18: 5 | NN18: 24 | NO18: 10 | NP18: 13 | NQ18: 20 | NR18: 23 | NS18: 20 | NT18: 18 | NU18: 13 | NV18: 21 | NW18: 25 | NX18: 30 | NY18: 26 | NZ18: 25 | OA18: 24 | OB18: 11 | OC18: 5 | OD18: 22 | OE18: 10 | OF18: 19 | OG18: 17 | OH18: 7 | OI18: 11 | OJ18: 29 | OK18: 23 | OL18: 6 | OM18: 11 | ON18: 24 | OO18: 10 | OP18: 30 | OQ18: 23 | OR18: 13 | OS18: 23 | OT18: 25 | OU18: 15 | OV18: 10 | OW18: 8 | OX18: 17 | OY18: 16 | OZ18: 25 | PA18: 13 | PB18: 14 | PC18: 10 | PD18: 11 | PE18: 5 | PF18: 7 | PG18: 7 | PH18: 8 | PI18: 17 | PJ18: 16 | PK18: 30 | PL18: 7 | PM18: 15 | PN18: 27 | PO18: 24 | PP18: 21 | PQ18: 26 | PR18: 9 | PS18: 16 | PT18: 28 | PU18: 8 | PV18: 19 | PW18: 22 | PX18: 19 | PY18: 11 | PZ18: 9 | QA18: 30 | QB18: 29 | QC18: 22 | QD18: 18 | QE18: 21 | QF18: 13 | QG18: 16 | QH18: 26 | QI18: 27 | QJ18: 28 | QK18: 30 | QL18: 5 | QM18: 21 | QN18: 16 | QO18: 13 | QP18: 9 | QQ18: 27 | QR18: 9 | QS18: 10 | QT18: 27 | QU18: 10 | QV18: 19 | QW18: 24 | QX18: 21 | QY18: 29 | QZ18: 8 | RA18: 23 | RB18: 16 | RC18: 23 | RD18: 25 | RE18: 30 | RF18: 24 | RG18: 16 | RH18: 10 | RI18: 15 | RJ18: 21 | RK18: 24 | RL18: 12 | RM18: 15 | RN18: 21 | RO18: 15 | RP18: 28 | RQ18: 9 | RR18: 15 | RS18: 14 | RT18: 20 | RU18: 21 | RV18: 29 | RW18: 22 | RX18: 22 | RY18: 15 | RZ18: 17 | SA18: 29 | SB18: 25 | SC18: 19 | SD18: 23 | SE18: 18 | SF18: 23 | SG18: 8 | SH18: 11 | SI18: 11 | SJ18: 14 | SK18: 27 | SL18: 9 | SM18: 5 | SN18: 21 | SO18: 21 | SP18: 7 | SQ18: 6 | SR18: 10 | SS18: 14 | ST18: 13 | SU18: 12 | SV18: 26 | SW18: 17 | SX18: 18 | SY18: 13 | SZ18: 22 | TA18: 11 | TB18: 26 | TC18: 29 | TD18: 13 | TE18: 29 | TF18: 28 | TG18: 15 | TH18: 17 | TI18: 22 | TJ18: 17 | TK18: 12 | TL18: 15 | TM18: 20 | TN18: 19 | TO18: 30 | TP18: 7 | TQ18: 8 | TR18: 25 | TS18: 12 | TT18: 22 | TU18: 11 | TV18: 18 | TW18: 8 | TX18: 15 | TY18: 18 | TZ18: 11 | UA18: 10 | UB18: 23 | UC18: 9 | UD18: 20 | UE18: 25 | UF18: 17 | UG18: 18 | UH18: 17 | UI18: 22 | UJ18: 6 | UK18: 27 | UL18: 8 | UM18: 18 | UN18: 23 | UO18: 16 | UP18: 27 | UQ18: 11 | UR18: 17 | US18: 28 | UT18: 24 | UU18: 22 | UV18: 18 | UW18: 28 | UX18: 20 | UY18: 19 | UZ18: 22 | VA18: 20 | VB18: 26 | VC18: 19 | VD18: 21 | VE18: 26 | VF18: 18 | VG18: 8 | VH18: 14 | VI18: 18 | VJ18: 8 | VK18: 16 | VL18: 23 | VM18: 27 | VN18: 8 | VO18: 20 | VP18: 11 | VQ18: 9 | VR18: 24 | VS18: 24 | VT18: 25 | VU18: 14 | VV18: 21 | VW18: 17 | VX18: 27 | VY18: 20 | VZ18: 16 | WA18: 26 | WB18: 5 | WC18: 17 | WD18: 24 | WE18: 23 | WF18: 11 | WG18: 24 | WH18: 22 | WI18: 28 | WJ18: 26 | WK18: 22 | WL18: 22 | WM18: 26 | WN18: 24 | WO18: 11 | WP18: 26 | WQ18: 30 | WR18: 17 | WS18: 7 | WT18: 18 | WU18: 17 | WV18: 20 | WW18: 17 | WX18: 10 | WY18: 27 | WZ18: 17 | XA18: 14 | XB18: 27 | XC18: 12 | XD18: 26 | XE18: 7 | XF18: 18 | XG18: 26 | XH18: 27 | XI18: 8 | XJ18: 12 | XK18: 5 | XL18: 28 | XM18: 13 | XN18: 14 | XO18: 19 | XP18: 18 | XQ18: 18 | XR18: 7 | XS18: 7 | XT18: 27 | XU18: 7 | XV18: 25 | XW18: 9 | XX18: 12 | XY18: 9 | XZ18: 5 | YA18: 23 | YB18: 25 | YC18: 28 | YD18: 17 | YE18: 10 | YF18: 16 | YG18: 12 | YH18: 29 | YI18: 10 | YJ18: 11 | YK18: 29 | YL18: 19 | YM18: 18 | YN18: 16 | YO18: 17 | YP18: 22 | YQ18: 8 | YR18: 23 | YS18: 17 | YT18: 18 | YU18: 21 | YV18: 9 | YW18: 22 | YX18: 14 | YY18: 10 | YZ18: 30 | ZA18: 30 | ZB18: 27 | ZC18: 21 | ZD18: 24 | ZE18: 15 | ZF18: 9 | ZG18: 8 | ZH18: 21 | ZI18: 25 | ZJ18: 7 | ZK18: 19 | ZL18: 11 | ZM18: 28 | ZN18: 26 | ZO18: 26 | ZP18: 8 | ZQ18: 5 | ZR18: 16 | ZS18: 23 | ZT18: 23 | ZU18: 26 | ZV18: 6 | ZW18: 27 | ZX18: 30 | ZY18: 21 | ZZ18: 15 | AAA18: 6 | AAB18: 24 | AAC18: 24 | AAD18: 12 | AAE18: 14 | AAF18: 11 | AAG18: 15 | AAH18: 20 | AAI18: 8 | AAJ18: 10 | AAK18: 8 | AAL18: 26 | AAM18: 17 | AAN18: 12 | AAO18: 17 | AAP18: 13 | AAQ18: 11 | AAR18: 21 | AAS18: 16 | AAT18: 14 | AAU18: 22 | AAV18: 29 | AAW18: 28 | AAX18: 18 | AAY18: 20 | AAZ18: 9 | ABA18: 17 | ABB18: 27 | ABC18: 21 | ABD18: 9 | ABE18: 26 | ABF18: 19 | ABG18: 25 | ABH18: 17 | ABI18: 7 | ABJ18: 10 | ABK18: 17 | ABL18: 22 | ABM18: 14 | ABN18: 11 | ABO18: 24 | ABP18: 5 | ABQ18: 8 | ABR18: 8 | ABS18: 7 | ABT18: 27 | ABU18: 29 | ABV18: 5 | ABW18: 14 | ABX18: 25 | ABY18: 6 | ABZ18: 20 | ACA18: 7 | ACB18: 23 | ACC18: 21 | ACD18: 17 | ACE18: 9 | ACF18: 17 | ACG18: 13 | ACH18: 20 | ACI18: 24 | ACJ18: 18 | ACK18: 13 | ACL18: 18 | ACM18: 21 | ACN18: 25 | ACO18: 5 | ACP18: 11 | ACQ18: 26 | ACR18: 19 | ACS18: 26 | ACT18: 26 | ACU18: 14 | ACV18: 22 | ACW18: 18 | ACX18: 25 | ACY18: 12 | ACZ18: 17 | ADA18: 30 | ADB18: 14 | ADC18: 27 | ADD18: 9 | ADE18: 10 | ADF18: 28 | ADG18: 14 | ADH18: 28 | ADI18: 16 | ADJ18: 8 | ADK18: 25 | ADL18: 23 | ADM18: 9 | ADN18: 23 | ADO18: 9 | ADP18: 22 | ADQ18: 15 | ADR18: 14 | ADS18: 13 | ADT18: 25 | ADU18: 5 | ADV18: 15 | ADW18: 21 | ADX18: 15 | ADY18: 21 | ADZ18: 19 | AEA18: 18 | AEB18: 22 | AEC18: 24 | AED18: 29 | AEE18: 16 | AEF18: 5 | AEG18: 24 | AEH18: 18 | AEI18: 13 | AEJ18: 19 | AEK18: 9 | AEL18: 22 | AEM18: 9 | AEN18: 14 | AEO18: 12 | AEP18: 17 | AEQ18: 14 | AER18: 16 | AES18: 28 | AET18: 15 | AEU18: 25 | AEV18: 19 | AEW18: 18 | AEX18: 21 | AEY18: 26 | AEZ18: 5 | AFA18: 13 | AFB18: 13 | AFC18: 18 | AFD18: 22 | AFE18: 13 | AFF18: 20 | AFG18: 10 | AFH18: 9 | AFI18: 29 | AFJ18: 20 | AFK18: 6 | AFL18: 17 | AFM18: 8 | AFN18: 21 | AFO18: 26 | AFP18: 7 | AFQ18: 15 | AFR18: 20 | AFS18: 16 | AFT18: 14 | AFU18: 28 | AFV18: 9 | AFW18: 18 | AFX18: 29 | AFY18: 13 | AFZ18: 24 | AGA18: 18 | AGB18: 8 | AGC18: 23 | AGD18: 21 | AGE18: 23 | AGF18: 30 | AGG18: 24 | AGH18: 9 | AGI18: 23 | AGJ18: 9 | AGK18: 24 | AGL18: 22 | AGM18: 7 | AGN18: 11 | AGO18: 6 | AGP18: 20 | AGQ18: 13 | AGR18: 15 | AGS18: 22 | AGT18: 9 | AGU18: 11 | AGV18: 23 | AGW18: 16 | AGX18: 18 | AGY18: 5 | AGZ18: 12 | AHA18: 16 | AHB18: 5 | AHC18: 17 | AHD18: 21 | AHE18: 7 | AHF18: 19 | AHG18: 6 | AHH18: 14 | AHI18: 7 | AHJ18: 10 | AHK18: 28 | AHL18: 5 | AHM18: 16 | AHN18: 11 | AHO18: 18 | AHP18: 7 | AHQ18: 10 | AHR18: 5 | AHS18: 11 | AHT18: 11 | AHU18: 17 | AHV18: 22 | AHW18: 29 | AHX18: 8 | AHY18: 10 | AHZ18: 7 | AIA18: 9 | AIB18: 12 | AIC18: 11 | AID18: 19 | AIE18: 7 | AIF18: 5 | AIG18: 18 | AIH18: 6 | AII18: 18 | AIJ18: 22 | AIK18: 13 | AIL18: 27 | AIM18: 19 | AIN18: 29 | AIO18: 23 | AIP18: 20 | AIQ18: 15 | AIR18: 20 | AIS18: 8 | AIT18: 11 | AIU18: 5 | AIV18: 30 | AIW18: 16 | AIX18: 18 | AIY18: 13 | AIZ18: 22 | AJA18: 21 | AJB18: 19 | AJC18: 29 | AJD18: 8 | AJE18: 9 | AJF18: 27 | AJG18: 5 | AJH18: 26 | AJI18: 28 | AJJ18: 17 | AJK18: 23 | AJL18: 13 | AJM18: 25 | AJN18: 20 | AJO18: 6 | AJP18: 10 | AJQ18: 24 | AJR18: 20 | AJS18: 6 | AJT18: 23 | AJU18: 23 | AJV18: 14 | AJW18: 6 | AJX18: 15 | AJY18: 7 | AJZ18: 20 | AKA18: 22 | AKB18: 27 | AKC18: 12 | AKD18: 9 | AKE18: 8 | AKF18: 29 | AKG18: 24 | AKH18: 6 | AKI18: 7 | AKJ18: 17 | AKK18: 11 | AKL18: 23 | AKM18: 13 | AKN18: 13 | AKO18: 19 | AKP18: 22 | AKQ18: 24 | AKR18: 27 | AKS18: 19 | AKT18: 5 | AKU18: 6 | AKV18: 6 | AKW18: 21 | AKX18: 19 | AKY18: 25 | AKZ18: 15 | ALA18: 10 | ALB18: 10 | ALC18: 15 | ALD18: 19 | ALE18: 25 | ALF18: 6 | ALG18: 6 | ALH18: 14 | ALI18: 11 | ALJ18: 14 | ALK18: 20 | ALL18: 10 | ALM18: 30 | ALN18: 26 | ALO18: 28 | ALP18: 17
A19: Mean | B19: =AVERAGE(Entertainment_Preferences!G2:G1001) -> 17.314
A20: Median | B20: =MEDIAN(Entertainment_Preferences!G2:G1001) -> 17
A21: Mode | B21: =MODE(Entertainment_Preferences!G2:G1001) -> 17
A22: Min | B22: =MIN(Entertainment_Preferences!G2:G1001) -> 5
A23: Max | B23: =MAX(Entertainment_Preferences!G2:G1001) -> 30
A24: Standard Deviation | B24: =_xlfn.STDEV.P(Entertainment_Preferences!G2:G1001) -> 7.3140552
A25: Variance | B25: =_xlfn.VAR.P(Entertainment_Preferences!G2:G1001) -> 53.495404
A26: Q1 | B26: =_xlfn.QUARTILE.INC(D18:ALP18,1) -> 11
A27: Q3 | B27: =_xlfn.QUARTILE.INC(E18:ALP18,3) -> 23
A28: IQR | B28: =B27-B26 -> 12
A39: 3. Does age influences the platform choice?
A40: Count of Primary_Platform | B40: Column Labels
A41: Age Group | B41: Amazon Prime | C41: Hotstar | D41: Netflix | E41: PlayStation | F41: Spotify | G41: Theatre | H41: TV | I41: YouTube | J41: Grand Total
A42: 18-23 | B42: 22 | C42: 39 | D42: 31 | E42: 35 | F42: 33 | G42: 33 | H42: 42 | I42: 36 | J42: 271
A43: 24-29 | B43: 38 | C43: 36 | D43: 44 | E43: 38 | F43: 37 | G43: 29 | H43: 33 | I43: 36 | J43: 291
A44: 30-35 | B44: 32 | C44: 23 | D44: 21 | E44: 28 | F44: 38 | G44: 33 | H44: 36 | I44: 31 | J44: 242
A45: 36-41 | B45: 23 | C45: 29 | D45: 30 | E45: 21 | F45: 23 | G45: 21 | H45: 24 | I45: 25 | J45: 196
A46: Grand Total | B46: 115 | C46: 127 | D46: 126 | E46: 122 | F46: 131 | G46: 116 | H46: 135 | I46: 128 | J46: 1000
A55: 4. What is the average monthly spending on entertainment?
A57: Preferred Entertainment | B57: Sum of Monthly_Spending_INR
A58: Sports | B58: 272559
A59: Gaming | B59: 261728
A60: OTT | B60: 254124
A61: Live Events | B61: 250838
A62: Music | B62: 250646
A63: Movies | B63: 248490
A64: Grand Total | B64: 1538385
A66: Analysis on Central Tendency
A67: Mean | B67: =AVERAGE(Entertainment_Preferences!I2:I1001) -> 1538.385
A68: Median | B68: =MEDIAN(Entertainment_Preferences!I2:I1001) -> 1555
...

Sheet Sheet8
M1: Education_Level | N1: Gender
B2: Gender | C2: Genre | K2: Grand Total | M2: School | N2: Male
C3: Action | D3: Comedy | E3: Drama | F3: Horror | G3: Pop | H3: Romance | I3: Sports | J3: Thriller | M3: PG | N3: Other
B4: Female | C4: 65378 | D4: 66179 | E4: 87860 | F4: 82041 | G4: 48552 | H4: 58173 | I4: 70019 | J4: 57595 | K4: 535797 | M4: School | N4: Female
B5: Male | C5: 55789 | D5: 70833 | E5: 53570 | F5: 56512 | G5: 53082 | H5: 68590 | I5: 77491 | J5: 68777 | K5: 504644 | M5: PG | N5: Other
B6: Other | C6: 54873 | D6: 65883 | E6: 74686 | F6: 50616 | G6: 50007 | H6: 67092 | I6: 68871 | J6: 65916 | K6: 497944 | M6: School | N6: Female
B7: Grand Total | C7: 176040 | D7: 202895 | E7: 216116 | F7: 189169 | G7: 151641 | H7: 193855 | I7: 216381 | J7: 192288 | K7: 1538385 | M7: PG | N7: Other
M8: UG | N8: Male
M9: UG | N9: Male
B10: Gender | C10: Metro | M10: UG | N10: Female
C11: Action | D11: Comedy | E11: Drama | F11: Horror | G11: Pop | H11: Romance | I11: Sports | J11: Thriller | K11: Grand Total | M11: PG | N11: Other
B12: Female | C12: 21050 | D12: 28736 | E12: 32656 | F12: 34743 | G12: 14096 | H12: 17469 | I12: 21999 | J12: 25882 | K12: 196631 | M12: UG | N12: Female
B13: Male | C13: 15157 | D13: 17617 | E13: 12573 | F13: 24982 | G13: 15559 | H13: 23778 | I13: 21706 | J13: 17789 | K13: 149161 | M13: UG | N13: Male
B14: Other | C14: 15653 | D14: 29454 | E14: 22226 | F14: 11659 | G14: 17644 | H14: 26038 | I14: 21071 | J14: 16576 | K14: 160321 | M14: UG | N14: Male
B15: Grand Total | C15: 51860 | D15: 75807 | E15: 67455 | F15: 71384 | G15: 47299 | H15: 67285 | I15: 64776 | J15: 60247 | K15: 506113 | M15: UG | N15: Male
M16: UG | N16: Female
M17: School | N17: Male
B18: Gender | C18: Rural | M18: School | N18: Other
C19: Action | D19: Comedy | E19: Drama | F19: Horror | G19: Pop | H19: Romance | I19: Sports | J19: Thriller | K19: Grand Total | M19: UG | N19: Female
B20: Female | C20: 20340 | D20: 20445 | E20: 27884 | F20: 22594 | G20: 15646 | H20: 17116 | I20: 26791 | J20: 12494 | K20: 163310 | M20: School | N20: Other
B21: Male | C21: 21367 | D21: 27787 | E21: 22964 | F21: 10219 | G21: 13854 | H21: 25034 | I21: 27189 | J21: 29668 | K21: 178082 | M21: PG | N21: Male
B22: Other | C22: 19555 | D22: 15846 | E22: 29408 | F22: 16333 | G22: 19363 | H22: 13950 | I22: 21066 | J22: 21412 | K22: 156933 | M22: School | N22: Male
B23: Grand Total | C23: 61262 | D23: 64078 | E23: 80256 | F23: 49146 | G23: 48863 | H23: 56100 | I23: 75046 | J23: 63574 | K23: 498325 | M23: PG | N23: Male
M24: School | N24: Other
M25: PG | N25: Male
M26: School | N26: Female
M27: School | N27: Female
C28: Gender | D28: Urban | M28: UG | N28: Male
D29: Action | E29: Comedy | F29: Drama | G29: Horror | H29: Pop | I29: Romance | J29: Sports | K29: Thriller | L29: Grand Total | M29: School | N29: Female
C30: Female | D30: 23988 | E30: 16998 | F30: 27320 | G30: 24704 | H30: 18810 | I30: 23588 | J30: 21229 | K30: 19219 | L30: 175856 | M30: PG | N30: Other
C31: Male | D31: 19265 | E31: 25429 | F31: 18033 | G31: 21311 | H31: 23669 | I31: 19778 | J31: 28596 | K31: 21320 | L31: 177401 | M31: School | N31: Male
C32: Other | D32: 19665 | E32: 20583 | F32: 23052 | G32: 22624 | H32: 13000 | I32: 27104 | J32: 26734 | K32: 27928 | L32: 180690 | M32: PG | N32: Male
C33: Grand Total | D33: 62918 | E33: 63010 | F33: 68405 | G33: 68639 | H33: 55479 | I33: 70470 | J33: 76559 | K33: 68467 | L33: 533947 | M33: UG | N33: Male
M34: PG | N34: Female
M35: UG | N35: Other
M36: PG | N36: Male
M37: PG | N37: Other
M38: School | N38: Other
M39: UG | N39: Other
M40: School | N40: Female
...
